Workbook

Sheet PF
E1: A | G1: B | K1: C | O1: D
C2: A-1 | E2: A0 | G2: B0 | K2: C0 | O2: D0
C3: Producto | D3: Consome | E3: Producto | F3: Consome | G3: Producto | H3: - | I3: Producto | J3: - | K3: Producto | L3: - | M3: Producto | N3: Consome | O3: Producto | P3: Consome
C4: Cantidad (cj) | D4: 100 | E4: Cantidad (cj) | F4: 80 | G4: Cantidad (cj) | H4: - | I4: Cantidad (cj) | J4: - | K4: Cantidad (cj) | L4: - | M4: Cantidad (cj) | N4: 48 | O4: Cantidad (cj) | P4: 100
C5: Lote | D5: =D16 -> 0 | E5: Lote | F5: 010625 | G5: Lote | H5: - | I5: Lote | J5: - | K5: Lote | L5: - | M5: Lote | N5: 010525 | O5: Lote | P5: 010625
A6: Producto | B6: Abreviatura | E6: A1 | G6: B1 | K6: C1 | O6: D1
A7: Consome | B7: Consome | E7: Producto | F7: Consome | G7: Producto | H7: Consome | I7: Producto | J7: Empaque | K7: Producto | L7: Empaque | M7: Producto | N7: Empaque | O7: Producto | P7: Empaque
A8: Mole almendrado | B8: Mo.Al | E8: Cantidad (cj) | F8: 100 | G8: Cantidad (cj) | H8: 100 | I8: Cantidad (cj) | J8: - | K8: Cantidad (cj) | L8: - | M8: Cantidad (cj) | N8: - | O8: Cantidad (cj) | P8: -
A9: Mole con Ajonjoli | B9: Mo.Aj | E9: Lote | F9: 010425 | G9: Lote | H9: - | I9: Lote | J9: - | K9: Lote | L9: - | M9: Lote | N9: - | O9: Lote | P9: -
A10: Mole Poblano | B10: Mo.Po | E10: A2 | G10: B2 | K10: C2 | O10: D2
A11: Chipotles | B11: Chipotles | E11: Producto | F11: =B9 -> Mo.Aj | G11: Producto | H11: =B9 -> Mo.Aj | I11: Producto | J11: - | K11: Producto | L11: C.M.P | M11: Producto | N11: =B12 -> C.M.P | O11: Producto | P11: =B12 -> C.M.P
A12: Cereza Materia prima | B12: C.M.P | E12: Cantidad (cj) | F12: 100 | G12: Cantidad (cj) | H12: 100 | I12: Cantidad (cj) | J12: - | K12: Cantidad (cj) | L12: 16 | M12: Cantidad (cj) | N12: 52 | O12: Cantidad (cj) | P12: 58
A13: Cereza Producto Final | B13: C.P.F | E13: Lote | F13: 010425 | G13: Lote | H13: 150425 | I13: Lote | J13: - | K13: Lote | L13: 1K05240109373 | M13: Lote | N13: 1K05240109373 | O13: Lote | P13: 1K05240109373
A14: Rajas | B14: Rajas | E14: A3 | G14: B3 | K14: C3 | O14: D3
A15: Empaques | B15: Empaque | E15: Producto | F15: =B9 -> Mo.Aj | G15: Producto | H15: =B8 -> Mo.Al | I15: Producto | J15: =B9 -> Mo.Aj | K15: Producto | L15: =B10 -> Mo.Po | M15: Producto | N15: =B13 -> C.P.F | O15: Producto | P15: Rajas
E16: Cantidad (cj) | F16: 84 | G16: Cantidad (cj) | H16: 81 | I16: Cantidad (cj) | J16: 47 | K16: Cantidad (cj) | L16: 27 | M16: Cantidad (cj) | N16: 71 | O16: Cantidad (cj) | P16: -
E17: Lote | G17: Lote | H17: 150425 | I17: Lote | J17: 010525 | K17: Lote | L17: 150525 | M17: Lote | N17: 151124 | O17: Lote | P17: -
E21: E | G21: F | I21: G | K21: H | M21: I
C22: E-1 | E22: E0 | G22: F0 | I22: G0 | K22: H0 | M22: I0
C23: Producto | D23: =B10 -> Mo.Po | E23: Producto | F23: =B10 -> Mo.Po | G23: Producto | H23: =B9 -> Mo.Aj | I23: Producto | J23: - | K23: Producto | L23: =B10 -> Mo.Po | M23: Producto | N23: =B9 -> Mo.Aj | O23: Producto | P23: Chipotle
C24: Cantidad (cj) | D24: 27 | E24: Cantidad (cj) | F24: 86 | G24: Cantidad (cj) | H24: 118 | I24: Cantidad (cj) | J24: - | K24: Cantidad (cj) | L24: 81 | M24: Cantidad (cj) | N24: 37 | O24: Cantidad (cj) | P24: 117
C25: Lote | D25: 010625 | E25: Lote | F25: 010625 | G25: Lote | H25: 010525 | I25: Lote | J25: - | K25: Lote | L25: 010525 | M25: Lote | N25: 010425 | O25: Lote | P25: 010625
E26: E1 | G26: F1 | I26: G1 | K26: H1 | M26: I1
E27: Producto | F27: Consome | G27: Producto | H27: Consome | I27: Producto | J27: Consome | K27: Producto | L27: Consome | M27: Producto | N27: Consome | O27: Producto | P27: Consome
E28: Cantidad (cj) | F28: 100 | G28: Cantidad (cj) | H28: 100 | I28: Cantidad (cj) | J28: 100 | K28: Cantidad (cj) | L28: 100 | M28: Cantidad (cj) | N28: 100 | O28: Cantidad (cj) | P28: 100
E29: Lote | F29: 010625 | G29: Lote | H29: - | I29: Lote | J29: 150525 | K29: Lote | L29: 150225 | M29: Lote | N29: 150525 | O29: Lote | P29: 150525
E30: E2 | G30: F2 | I30: G2 | K30: H2 | M30: I2
E31: Producto | F31: Consome | G31: Producto | H31: Consome | I31: Producto | J31: Consome | K31: Producto | L31: Consome | M31: Producto | N31: =B9 -> Mo.Aj | O31: Producto | P31: =B10 -> Mo.Po
E32: Cantidad (cj) | F32: 100 | G32: Cantidad (cj) | H32: 100 | I32: Cantidad (cj) | J32: 100 | K32: Cantidad (cj) | L32: 100 | M32: Cantidad (cj) | N32: 100 | O32: Cantidad (cj) | P32: 100
E33: Lote | F33: 150525 | G33: Lote | H33: 010625 | I33: Lote | J33: 010625 | K33: Lote | L33: 150525 | M33: Lote | O33: Lote
E34: E3 | G34: F3 | I34: G3 | K34: H3 | M34: I3
E35: Producto | F35: =B10 -> Mo.Po | G35: Producto | H35: =B8 -> Mo.Al | I35: Producto | J35: =B12 -> C.M.P | K35: Producto | L35: =B8 -> Mo.Al | M35: Producto | N35: =B8 -> Mo.Al | O35: Producto | P35: Chipotle
E36: Cantidad (cj) | F36: 100 | G36: Cantidad (cj) | H36: 107 | I36: Cantidad (cj) | J36: 60 | K36: Cantidad (cj) | L36: 78 | M36: Cantidad (cj) | N36: 95 | O36: Cantidad (cj) | P36: 53
E37: Lote | F37: 150325 | G37: Lote | H37: 010425 | I37: Lote | J37: 1K05240109373 | K37: Lote | L37: - | M37: Lote | N37: 15.04.25 15.05.25 01.03.25 | O37: Lote | P37: 01.03.25 15.05.25
E38: E4 | G38: F4 | I38: G4
E39: Producto | F39: =B10 -> Mo.Po | G39: Producto | H39: =B8 -> Mo.Al | I39: Producto | J39: C.M.P
E40: Cantidad (cj) | F40: 48 | G40: Cantidad (cj) | H40: 90 | I40: Cantidad (cj) | J40: 60
E41: Lote | F41: 010525 | G41: Lote | H41: 010525 | I41: Lote | J41: 1K05240109373
C42: E-5 | E42: E5 | G42: F5 | I42: G5
C43: Producto | D43: =B10 -> Mo.Po | E43: Producto | F43: =B10 -> Mo.Po | G43: Producto | H43: =B8 -> Mo.Al | I43: Producto | J43: C.M.P
...

Sheet BDPF
A1: Rack | B1: Nivel | C1: Espacio | D1: Lote | E1: Producto | F1: Cantidad (pz) | G1: Kilo por pieza | H1: Total Kilogramos | I1: Lote anexado | J1: Observaciones
A2: 1 | B2: A | C2: A-1 | D2: =PF!$D$5 -> 0 | E2: =PF!D3 -> Consome | F2: =PF!D4 -> 100 | H2: =F2*G2 -> 0
C3: A0 | D3: =PF!$F$5 | E3: =PF!F3 -> Consome | F3: =PF!F4 -> 80 | H3: =F3*G3 -> 0
C4: A1 | D4: =PF!$F$13 | E4: =PF!F7 -> Consome | F4: 100 | H4: =F4*G4 -> 0 | L4: Rack 3 | M4: Presentaciòn | N4: Lote | O4: Producto | P4: Cantidad (PZ) | Q4: Observaciones
C5: A2 | D5: =PF!$F$13 | E5: =PF!F11 -> Mo.Aj | F5: 100 | H5: =F5*G5 -> 0 | M5: 1KG | N5: =PF!$H$64 -> 0 | O5: =PF!$H$62 -> 0 | P5: =PF!$H$63 -> 0
C6: A3 | D6: =PF!$F$17 -> 0 | E6: =PF!F15 -> Mo.Aj | F6: 84 | H6: =F6*G6 -> 0 | M6: 2KG | N6: =PF!$F$64 -> 0 | O6: =PF!$F$62 -> 0 | P6: =PF!$F$63 -> 0
B7: B | C7: B0I | D7: =PF!$H$5 -> - | E7: =PF!H3 -> - | F7: =PF!H4 -> - | H7: =F7*G7 -> #VALUE! | M7: 3KG | N7: =PF!$D$64 -> 0 | O7: =PF!$D$62 -> 0 | P7: =PF!$D$63 -> 0
C8: B0D | D8: =PF!$J$5 -> - | E8: =PF!J3 -> - | F8: =PF!J4 -> - | H8: =F8*G8 -> #VALUE! | M8: 5KG | N8: =PF!$J$60 -> 0 | O8: =PF!$J$58 -> 0 | P8: =PF!$J$59 -> 0
C9: B1I | D9: =PF!$H$9 -> - | E9: =PF!H7 -> Consome | F9: =PF!H8 -> 100 | H9: =F9*G9 -> 0 | M9: 5KG(Premium) | N9: =PF!$J$64 -> 0 | O9: =PF!$J$62 -> 0 | P9: =PF!$J$63 -> 0
C10: B1D | D10: =PF!$J$9 -> - | E10: =PF!J7 -> Empaque | F10: =PF!J8 -> - | H10: =F10*G10 -> #VALUE! | M10: 6KG | N10: =PF!$L$60 -> 0 | O10: =PF!$L$58 -> 0 | P10: =PF!$L$59 -> 0
C11: B2I | D11: =PF!$H$13 -> 150425 | E11: =PF!H11 -> Mo.Aj | F11: =PF!H12 -> 100 | H11: =F11*G11 -> 0 | M11: 10KG | N11: =PF!$L$64 -> 0 | O11: =PF!$L$62 -> 0 | P11: =PF!$L$63 -> 0
C12: B2D | D12: =PF!$J$13 -> - | E12: =PF!J11 -> - | F12: =PF!J12 -> - | H12: =F12*G12 -> #VALUE!
C13: B3I | D13: =PF!$H$17 -> 150425 | E13: =PF!H15 -> Mo.Al | F13: =PF!H16 -> 81 | H13: =F13*G13 -> 0
C14: B3D | D14: =PF!$J$17 -> 010525 | E14: =PF!J15 -> Mo.Aj | F14: =PF!J16 -> 47 | H14: =F14*G14 -> 0 | L14: Moles a Granel | M14: Nivel | N14: Posición | O14: Lote | P14: Producto | Q14: Cantidad (Kg) | R14: Cantidad empaquetada(Kg) | S14: Total | T14: Observaciones
B15: C | C15: C0I | D15: =PF!$L$5 -> - | E15: =PF!L3 -> - | F15: =PF!L4 -> - | H15: =F15*G15 -> #VALUE! | M15: Mo.Al | N15: Mo.Al 1 | O15: =PF!C70 -> 0 | P15: =PF!C68 -> 0 | Q15: =PF!C69 -> 0 | S15: =Q15-R15 -> 0
C16: C0D | D16: =PF!$N$5 -> 010525 | E16: =PF!N3 -> Consome | F16: =PF!N4 -> 48 | H16: =F16*G16 -> 0 | O16: =PF!C73 -> 0 | P16: =PF!C71 -> 0 | Q16: =PF!C75 -> 0 | S16: =Q16-R16 -> 0
C17: C1I | D17: =PF!$L$9 -> - | E17: =PF!L7 -> Empaque | F17: =PF!L8 -> - | H17: =F17*G17 -> #VALUE! | O17: =PF!C76 -> 0 | P17: =PF!C74 -> 0 | Q17: =PF!C75 -> 0 | S17: =Q17-R17 -> 0
C18: C1D | D18: =PF!$N$9 -> - | E18: =PF!N7 -> Empaque | F18: =PF!N8 -> - | H18: =F18*G18 -> #VALUE! | N18: Mo.Al 2 | O18: =PF!E70 -> 0 | P18: =PF!E68 -> 0 | Q18: =PF!E69 -> 0 | S18: =Q18-R18 -> 0
C19: C2I | D19: =PF!$L$13 -> 1K05240109373 | E19: =PF!L11 -> C.M.P | F19: =PF!L12 -> 16 | H19: =F19*G19 -> 0 | O19: =PF!G73 -> 0 | P19: =PF!E71 -> 0 | Q19: =PF!E72 -> 0 | S19: =Q19-R19 -> 0
C20: C2D | D20: =PF!$N$13 -> 1K05240109373 | E20: =PF!N11 -> C.M.P | F20: =PF!N12 -> 52 | H20: =F20*G20 -> 0 | O20: =PF!E76 -> 0 | P20: =PF!E74 -> 0 | Q20: =PF!E75 -> 0 | S20: =Q20-R20 -> 0
C21: C3I | D21: =PF!$L$17 -> 150525 | E21: =PF!L15 -> Mo.Po | F21: =PF!L16 -> 27 | H21: =F21*G21 -> 0 | M21: Mo.Aj | N21: Mo.Aj 1 | O21: =PF!G70 -> 0 | P21: =PF!G68 -> 0 | Q21: =PF!G69 -> 0 | S21: =Q21-R21 -> 0
C22: C3D | D22: =PF!$N$17 -> 151124 | E22: =PF!N15 -> C.P.F | F22: =PF!N16 -> 71 | H22: =F22*G22 -> 0 | O22: =PF!G73 -> 0 | P22: =PF!G71 -> 0 | Q22: =PF!G72 -> 0 | S22: =Q22-R22 -> 0
B23: D | C23: D0 | D23: =PF!$P$5 | E23: =PF!P3 -> Consome | F23: =PF!P4 -> 100 | H23: =F23*G23 -> 0 | O23: =PF!G76 -> 0 | P23: =PF!G74 -> 0 | Q23: =PF!G75 -> 0 | S23: =Q23-R23 -> 0
C24: D1 | D24: =PF!$P$9 -> - | E24: =PF!P7 -> Empaque | F24: =PF!P8 -> - | H24: =F24*G24 -> #VALUE! | N24: Mo.Aj 2 | O24: =PF!I70 -> 0 | P24: =PF!I68 -> 0 | Q24: =PF!I69 -> 0 | S24: =Q24-R24 -> 0
C25: D2 | D25: =PF!$P$13 -> 1K05240109373 | E25: =PF!P11 -> C.M.P | F25: =PF!P12 -> 58 | H25: =F25*G25 -> 0 | O25: =PF!I73 -> 0 | P25: =PF!I71 -> 0 | Q25: =PF!I72 -> 0 | S25: =Q25-R25 -> 0
C26: D3 | D26: =PF!$P$17 -> - | E26: =PF!P15 -> Rajas | F26: =PF!P16 -> - | H26: =F26*G26 -> #VALUE! | O26: =PF!I76 -> 0 | P26: =PF!I74 -> 0 | Q26: =PF!I75 -> 0 | S26: =Q26-R26 -> 0
A27: 2 | B27: E | C27: E-1 | D27: =PF!$D$25 | E27: =PF!D23 -> Mo.Po | F27: =PF!D24 -> 27 | H27: =F27*G27 -> 0 | M27: Mo.Po | N27: Mo.Po 1 | O27: =PF!K70 -> 0 | P27: =PF!K68 -> 0 | Q27: =PF!K69 -> 0 | S27: =Q27-R27 -> 0
C28: E0 | D28: =PF!$F$25 | E28: =PF!F23 -> Mo.Po | F28: =PF!F24 -> 86 | H28: =F28*G28 -> 0 | O28: =PF!K73 -> 0 | P28: =PF!K71 -> 0 | Q28: =PF!K72 -> 0 | S28: =Q28-R28 -> 0
C29: E1 | D29: =PF!$F$29 -> 010625 | E29: =PF!F27 -> Consome | F29: =PF!F28 -> 100 | H29: =F29*G29 -> 0 | O29: =PF!K76 -> 0 | P29: =PF!K74 -> 0 | Q29: =PF!K75 -> 0 | S29: =Q29-R29 -> 0
C30: E2 | D30: =PF!$F$33 -> 150525 | E30: =PF!F31 -> Consome | F30: =PF!F32 -> 100 | H30: =F30*G30 -> 0 | N30: Mo.Po 2 | O30: =PF!M70 -> 0 | P30: =PF!M68 -> 0 | Q30: =PF!M69 -> 0 | S30: =Q30-R30 -> 0
C31: E3 | D31: =PF!$F$37 -> 150325 | E31: =PF!F35 -> Mo.Po | F31: =PF!F36 -> 100 | H31: =F31*G31 -> 0 | O31: =PF!M73 -> 0 | P31: =PF!M71 -> 0 | Q31: =PF!M72 -> 0 | S31: =Q31-R31 -> 0
C32: E4 | D32: =PF!$F$41 -> 010525 | E32: =PF!F39 -> Mo.Po | F32: =PF!F40 -> 48 | H32: =F32*G32 -> 0 | O32: =PF!M76 -> 0 | P32: =PF!M74 -> 0 | Q32: =PF!M75 -> 0 | S32: =Q32-R32 -> 0
C33: E5 | D33: =PF!$F$45 -> 01.05.25 15.04.25 | E33: =PF!F43 -> Mo.Po | F33: =PF!F44 -> 100 | H33: =F33*G33 -> 0
C34: E-5 | D34: =PF!$D$45 | E34: =PF!D43 -> Mo.Po | F34: =PF!D44 -> 113 | H34: =F34*G34 -> 0 | L34: Pipian | M34: Nivel | N34: Lote | O34: Producto | P34: Cantidad(Kg) | Q34: Cantidad empaquetada | R34: Total | S34: Observaciones
B35: F | C35: F0 | D35: =PF!$H$25 | E35: =PF!H23 -> Mo.Aj | F35: =PF!H24 -> 118 | H35: =F35*G35 -> 0 | M35: PI1 | N35: =PF!E83 -> 0 | O35: =PF!E81 -> 0 | P35: =PF!E82 -> 0 | R35: =P35-Q35 -> 0
C36: F1 | D36: =PF!$H$29 -> - | E36: =PF!H27 -> Consome | F36: =PF!H28 -> 100 | H36: =F36*G36 -> 0 | N36: =PF!E86 -> 0 | O36: =PF!E84 -> 0 | P36: =PF!E85 -> 0 | R36: =P36-Q36 -> 0
C37: F2 | D37: =PF!$H$33 -> 010625 | E37: =PF!H31 -> Consome | F37: =PF!H32 -> 100 | H37: =F37*G37 -> 0 | M37: PI2 | N37: =PF!G83 -> 0 | O37: =PF!G81 -> 0 | P37: =PF!G82 -> 0 | R37: =P37-Q37 -> 0
C38: F3 | D38: =PF!D37 -> 0 | E38: =PF!H35 -> Mo.Al | F38: =PF!H36 -> 107 | H38: =F38*G38 -> 0 | N38: =PF!G86 -> 0 | O38: =PF!G84 -> 0 | P38: =PF!G85 -> 0 | R38: =P38-Q38 -> 0
C39: F4 | D39: =PF!$H$41 -> 010525 | E39: =PF!H39 -> Mo.Al | F39: =PF!H40 -> 90 | H39: =F39*G39 -> 0 | M39: PI3 | N39: =PF!I83 -> 0 | O39: =PF!I81 -> 0 | P39: =PF!I82 -> 0 | R39: =P39-Q39 -> 0
C40: F5 | D40: =PF!$H$45 -> 150525 | E40: =PF!H43 -> Mo.Al | F40: =PF!H44 -> 81 | H40: =F40*G40 -> 0 | N40: =PF!I86 -> 0 | O40: =PF!I84 -> 0 | P40: =PF!I85 -> 0 | R40: =P40-Q40 -> 0
...

Sheet MEP
B2: Consome | E2: Lote | F2: Mole | I2: Lote
B3: PVH | F3: Mole
B4: Unidades(Pz) | F4: Unidades (pz)
B5: Materiales (kg) | F5: Materiales (kg)
B6: PVH | C6: 3 | D6: =C6*$D$4 -> 0 | F6: Anis | G6: 1.2 | H6: =G6*$D$50 -> 0
B7: Maltodextrina | C7: 4 | D7: =C7*$D$4 -> 0 | F7: Canela | G7: 0.5 | H7: =G7*$D$50 -> 0
B8: Ajo Molido | C8: 0.4 | D8: =C8*$D$4 -> 0 | F8: Clavo | G8: 0.2 | H8: =G8*$D$50 -> 0
B9: Cebolla Molida | C9: 0.4 | D9: =C9*$D$4 -> 0 | F9: Chocolate | G9: 3 | H9: =G9*$D$50 -> 0
B10: Glutamato | C10: 2 | D10: =C10*$D$4 -> 0
B11: Curcuma y laca
B12: Unidades (pz)
B13: Materiales (kg)
B14: Curcuma | C14: 0.4 | D14: =C14*$K$41 -> 0
B15: Laca | C15: 0.08 | D15: =C15*$K$41 -> 0
B16: Fecula de Almidòn
B17: Unidades(pz)
B18: Materiales (kg)
B19: Almidon | C19: 14 | D19: =C19*$L$41 -> 0
B20: Perejil | C20: 0.2 | D20: =C20*$L$41 -> 0

Sheet MP
E2: Materia Prima Planta Baja
E3: J | G3: K | I3: L | K3: M | M3: N | O3: O | Q3: P
G4: K-1 | I4: L-1
G5: Materia | H5: Sal | I5: Materia | J5: Cacahuate
G6: Cantidad (pz) | H6: 45 | I6: Cantidad (pz) | J6: 16
G7: Lote | H7: - | I7: Lote | J7: -
G8: Materia | I8: Materia
G9: Cantidad (pz) | I9: Cantidad (pz)
G10: Lote 2 | I10: Lote 2
G11: K0 | I11: L0 | O11: O0 | Q11: P0
G12: Materia | H12: Sal | I12: Materia | J12: Chocolate | O12: Materia | P12: Aceite | Q12: Materia | R12: Aceite
G13: Cantidad (pz) | H13: 45 | I13: Cantidad (pz) | J13: 35 | O13: Cantidad (pz) | P13: 100 | Q13: Cantidad (pz) | R13: 100
G14: Lote | H14: - | I14: Lote | J14: - | O14: Lote | P14: - | Q14: Lote | R14: -
G15: Materia | I15: Materia | O15: Materia | Q15: Materia
G16: Cantidad (pz) | I16: Cantidad (pz) | O16: Cantidad (pz) | Q16: Cantidad (pz)
G17: Lote 2 | I17: Lote 2 | O17: Lote 2 | Q17: Lote 2
E18: J1 | G18: K1 | I18: L1 | K18: M1 | M18: N1 | O18: O1 | Q18: P1
E19: Materia | F19: Ajonjoli B | G19: Materia | H19: Ajonjoli N | I19: Materia | J19: Ajonjoli N | K19: Materia | L19: ANIS | M19: Materia | N19: Canela | O19: Materia | P19: Platano | Q19: Materia | R19: Platano
E20: Cantidad (pz) | F20: 15 | G20: Cantidad (pz) | H20: 55 | I20: Cantidad (pz) | J20: 55 | K20: Cantidad (pz) | L20: 63.4 | M20: Cantidad (pz) | N20: 137.6 | O20: Cantidad (pz) | P20: 28 | Q20: Cantidad (pz) | R20: 35
E21: Lote 1 | F21: - | G21: Lote | H21: - | I21: Lote | J21: - | K21: Lote | L21: - | M21: Lote | N21: - | O21: Lote | P21: - | Q21: Lote | R21: -
E22: Materia | G22: Materia | I22: Materia | K22: Materia | M22: Materia | O22: Materia | Q22: Materia
E23: Cantidad (pz) | G23: Cantidad (pz) | I23: Cantidad (pz) | K23: Cantidad (pz) | M23: Cantidad (pz) | O23: Cantidad (pz) | Q23: Cantidad (pz)
E24: Lote 2 | G24: Lote 2 | I24: Lote 2 | K24: Lote 2 | M24: Lote 2 | O24: Lote 2 | Q24: Lote 2
E25: J2 | G25: K2 | I25: L2 | K25: M2 | O25: O2 | Q25: P2
E26: Materia | F26: Cacahuate | G26: Materia | H26: Cacahuate | I26: Materia | J26: Cacahuate | K26: Materia | L26: Galleta | O26: Materia | P26: Varios | Q26: Materia | R26: Varios
E27: Cantidad (pz) | F27: 30 | G27: Cantidad (pz) | H27: 35 | I27: Cantidad (pz) | J27: 11 | K27: Cantidad (pz) | L27: 23 | O27: Cantidad (pz) | Q27: Cantidad (pz)
E28: Lote | F28: - | G28: Lote | H28: - | I28: Lote | J28: - | K28: Lote | L28: - | O28: Lote | P28: - | Q28: Lote | R28: -
E29: Materia | G29: Materia | I29: Materia | K29: Materia | O29: Materia | Q29: Materia
E30: Cantidad (pz) | G30: Cantidad (pz) | I30: Cantidad (pz) | K30: Cantidad (pz) | O30: Cantidad (pz) | Q30: Cantidad (pz)
E31: Lote 2 | G31: Lote 2 | I31: Lote 2 | K31: Lote 2 | O31: Lote 2 | Q31: Lote 2
E32: J3 | G32: K3 | I32: L3 | K32: M3 | O32: O3 | Q32: P3
E33: Materia | F33: Aceite | G33: Materia | H33: - | I33: Materia | J33: - | K33: Materia | L33: - | O33: Materia | P33: Azucar | Q33: Materia | R33: Azucar
E34: Cantidad (pz) | F34: 48 | G34: Cantidad (pz) | H34: - | I34: Cantidad (pz) | J34: - | K34: Cantidad (pz) | L34: - | O34: Cantidad (pz) | P34: 62 | Q34: Cantidad (pz) | R34: 62
E35: Lote | F35: - | G35: Lote | H35: - | I35: Lote | J35: - | K35: Lote | L35: - | O35: Lote | P35: - | Q35: Lote | R35: -
E36: Materia | G36: Materia | I36: Materia | K36: Materia | O36: Materia | Q36: Materia
E37: Cantidad (pz) | G37: Cantidad (pz) | I37: Cantidad (pz) | K37: Cantidad (pz) | O37: Cantidad (pz) | Q37: Cantidad (pz)
E38: Lote 2 | G38: Lote 2 | I38: Lote 2 | K38: Lote 2 | O38: Lote 2 | Q38: Lote 2
E39: J4 | G39: K4 | I39: L4 | K39: M4 | O39: O4 | Q39: P4
E40: Materia | F40: Aceite | G40: Materia | H40: - | I40: Materia | J40: - | K40: Materia | L40: - | O40: Materia | P40: Aceite | Q40: Materia | R40: Aceite
E41: Cantidad (pz) | F41: 50 | G41: Cantidad (pz) | H41: - | I41: Cantidad (pz) | J41: - | K41: Cantidad (pz) | L41: - | O41: Cantidad (pz) | P41: 48 | Q41: Cantidad (pz) | R41: 48
...

Sheet BDMP
A1: Almacen | B1: Nivel | C1: Espacio | D1: Lote | E1: Materia | F1: Cantidad (pz) | G1: Peso por pieza | H1: Cantidad Ocupada | I1: Cantidad Actualizada | J1: Total Cantidad | K1: Bultos | L1: Observaciones
A2: PLANTA BAJA | B2: J | C2: J1 | D2: =MP!B21 -> 0 | E2: =MP!F19 -> Ajonjoli B | F2: =MP!F20 -> 15 | G2: 25 | H2: =Hoja2!W3 -> 0 | I2: =(E2*F2)-H2 -> #VALUE! | J2: =I2+I3 -> #VALUE! | K2: =J2/F2 -> #VALUE!
D3: =MP!B24 -> 0 | E3: =MP!F22 -> 0 | F3: =MP!F23 -> 0 | G3: 25 | H3: 200 | I3: =(F3*G3)-H3 -> -200
C4: J2 | E4: =MP!F26 -> Cacahuate | F4: =MP!F27 -> 30 | G4: 2 | I4: =(E4*F4)-H4 -> #VALUE! | J4: =I4+I5 -> #VALUE! | K4: =J4/F5 -> #VALUE!
D5: =MP!B31 -> 0 | E5: =MP!F29 -> 0 | F5: =MP!F30 -> 0 | G5: 12 | I5: =(E5*F5)-H5 -> 0
C6: J3 | D6: =MP!B35 -> 0 | E6: =MP!F33 -> Aceite | F6: =MP!F34 -> 48 | I6: =(E6*F6)-H6 -> #VALUE! | J6: =I6+I8 -> #VALUE!
D7: =MP!B38 -> 0 | E7: =MP!F36 -> 0 | F7: =MP!F37 -> 0 | I7: =(E7*F7)-H7 -> 0
C8: J4 | D8: =MP!B42 -> 0 | E8: =MP!F40 -> Aceite | F8: =MP!F41 -> 50 | I8: =(E8*F8)-H8 -> #VALUE! | J8: =I8+I9 -> #VALUE! | K8: =J8/F8 -> #VALUE! | O8: x
D9: =MP!B45 -> 0 | E9: =MP!F43 -> 0 | I9: =(E9*F9)-H9 -> 0
B10: K | C10: K-1 | D10: =MP!D7 -> 0 | E10: =MP!H5 -> Sal | F10: =MP!H6 -> 45 | I10: =(E10*F10)-H10 -> #VALUE! | J10: =I10+I11 -> #VALUE! | K10: =J10/F10 -> #VALUE!
D11: =MP!D10 -> 0 | E11: =MP!H8 -> 0 | F11: =MP!H9 -> 0 | I11: =(E11*F11)-H11 -> 0
C12: K0 | D12: =MP!D14 -> 0 | E12: =MP!H12 -> Sal | F12: =MP!H13 -> 45 | I12: =(E12*F12)-H12 -> #VALUE! | J12: =I12+I13 -> #VALUE! | K12: =J12/F12 -> #VALUE!
D13: =MP!D17 -> 0 | E13: =MP!H15 -> 0 | F13: =MP!H16 -> 0 | I13: =(E13*F13)-H13 -> 0
C14: K1 | D14: =MP!D21 -> 0 | E14: =MP!H19 -> Ajonjoli N | F14: =MP!H20 -> 55 | I14: =(E14*F14)-H14 -> #VALUE! | J14: =I14+I15 -> #VALUE! | K14: =J14/F14 -> #VALUE!
D15: =MP!D24 -> 0 | E15: =MP!H22 -> 0 | F15: =MP!H23 -> 0 | I15: =(E15*F15)-H15 -> 0
C16: K2 | D16: =MP!D28 -> 0 | E16: =MP!H26 -> Cacahuate | F16: =MP!H27 -> 35 | I16: =(E16*F16)-H16 -> #VALUE! | J16: =I16+I17 -> #VALUE! | K16: =J16/F16 -> #VALUE!
D17: =MP!D31 -> 0 | E17: =MP!H29 -> 0 | F17: =MP!H30 -> 0 | I17: =(E17*F17)-H17 -> 0
C18: K3 | D18: =MP!D35 -> 0 | E18: =MP!H33 -> - | F18: =MP!H34 -> - | I18: =(E18*F18)-H18 -> #VALUE! | J18: =I18+I19 -> #VALUE! | K18: =J18/F18 -> #VALUE!
D19: =MP!D38 -> 0 | E19: =MP!H36 -> 0 | F19: =MP!H37 -> 0
C20: K4 | D20: =MP!D42 -> 0 | E20: =MP!H40 -> - | F20: =MP!H41 -> - | I20: =(E20*F20)-H20 -> #VALUE! | J20: =I20+I21 -> #VALUE! | K20: =J20/F20 -> #VALUE!
D21: =MP!D45 -> 0 | E21: =MP!H43 -> 0 | F21: =MP!H44 -> 0 | I21: =(E21*F21)-H21 -> 0
B22: L | C22: L-1 | D22: =MP!F7 -> 0 | E22: =MP!J5 -> Cacahuate | F22: =MP!J6 -> 16 | I22: =(E22*F22)-H22 -> #VALUE! | J22: =I22+I23 -> #VALUE! | K22: =J22/F22 -> #VALUE!
D23: =MP!F10 -> 0 | E23: =MP!J8 -> 0 | F23: =MP!J9 -> 0 | I23: =(E23*F23)-H23 -> 0
C24: L0 | D24: =MP!F14 -> 0 | E24: Cacahuate | F24: 12 | I24: =(E24*F24)-H24 -> #VALUE! | J24: =I24+I25 -> #VALUE! | K24: =J24/F24 -> #VALUE!
D25: =MP!F17 -> 0 | E25: =MP!J15 -> 0 | F25: =MP!J16 -> 0 | I25: =(E25*F25)-H25 -> 0
C26: L1 | D26: =MP!F21 -> - | E26: =MP!J19 -> Ajonjoli N | F26: =MP!J20 -> 55 | I26: =(E26*F26)-H26 -> #VALUE! | J26: =I26+I27 -> #VALUE! | K26: =J26/F26 -> #VALUE!
D27: =MP!F24 -> 0 | E27: =MP!J22 -> 0 | F27: =MP!J23 -> 0 | I27: =(E27*F27)-H27 -> 0
C28: L2 | D28: =MP!F28 -> - | E28: =MP!J26 -> Cacahuate | F28: =MP!J27 -> 11 | I28: =(E28*F28)-H28 -> #VALUE! | J28: =I28+I29 -> #VALUE! | K28: =J28/F28 -> #VALUE!
D29: =MP!F31 -> 0 | E29: =MP!J29 -> 0 | F29: =MP!J30 -> 0 | I29: =(E29*F29)-H29 -> 0
C30: L3 | D30: 155234 | E30: Ajonjoli | F30: 34 | G30: 10 | H30: =Hoja2!#REF! -> #REF! | I30: =(E30*F30)-H30 -> #VALUE! | J30: =I30+I31 -> #VALUE! | K30: =J30/F30 -> #VALUE!
D31: =MP!F38 -> 0 | E31: =MP!J36 -> 0 | F31: =MP!J37 -> 0 | I31: =(E31*F31)-H31 -> 0
C32: L4 | D32: =MP!F42 -> - | E32: =MP!J40 -> - | F32: =MP!J41 -> - | I32: =(E32*F32)-H32 -> #VALUE! | J32: =I32+I33 -> #VALUE! | K32: =J32/F32 -> #VALUE!
D33: =MP!F45 -> 0 | E33: =MP!J43 -> 0 | F33: =MP!J44 -> 0 | I33: =(E33*F33)-H33 -> 0
B34: M | C34: M1 | D34: =MP!H21 -> - | E34: =MP!L19 -> ANIS | F34: =MP!L20 -> 63.4 | I34: =(E34*F34)-H34 -> #VALUE! | J34: =I34+I35 -> #VALUE! | K34: =J34/F34 -> #VALUE!
D35: =MP!H24 -> 0 | E35: =MP!L22 -> 0 | F35: =MP!L23 -> 0 | I35: =(E35*F35)-H35 -> 0
C36: M2 | D36: =MP!H28 -> - | E36: =MP!L26 -> Galleta | F36: =MP!L27 -> 23 | I36: =(E36*F36)-H36 -> #VALUE! | J36: =I36+I37 -> #VALUE! | K36: =J36/F36 -> #VALUE!
D37: =MP!H31 -> 0 | E37: =MP!L29 -> 0 | F37: =MP!L30 -> 0 | I37: =(E37*F37)-H37 -> 0
C38: M3 | D38: =MP!H35 -> - | E38: =MP!L33 -> - | F38: =MP!L34 -> - | I38: =(E38*F38)-H38 -> #VALUE! | J38: =I38+I39 -> #VALUE! | K38: =J38/F38 -> #VALUE!
D39: =MP!H38 -> 0 | E39: =MP!L36 -> 0 | F39: =MP!L37 -> 0 | I39: =(E39*F39)-H39 -> 0
C40: M4 | D40: =MP!H42 -> - | E40: =MP!L40 -> - | F40: =MP!L41 -> - | I40: =(E40*F40)-H40 -> #VALUE! | J40: =I40+I41 -> #VALUE! | K40: =J40/F40 -> #VALUE!
...

Sheet Hoja2
A1: SALIDA DE ALMACEN
A2: PRODUCTO | B2: LOTES | C2: 45694 | D2: 45722 | E2: 45753 | F2: 45783 | G2: 45814 | H2: 45906 | I2: 45936 | J2: 45967 | K2: 45820 | L2: 45821 | M2: 6/16/2025 | N2: 6/17/2025 | O2: 6/18/2025 | P2: 6/19/2025 | Q2: 6/20/2025 | R2: 6/23/2025 | S2: 6/24/2025 | T2: 6/25/2025 | U2: 6/26/2025 | V2: 6/27/2025 | W2: 6/30/2025 | X2: Total
A3: Aceite (litros) | B3: 10203 | C3: 42 | D3: 111 | E3: 150 | F3: 105 | G3: 105 | K3: 152 | M3: 190 | X3: =SUM(C3:W3) -> 855
B4: 10506 | X4: =SUM(C4:W4) -> 0
A5: Ajo molido | C5: 5.6 | D5: 3.6 | E5: 3.6 | F5: 2.4 | G5: 0.6 | X5: =SUM(C5:W5) -> 15.8
X6: =SUM(C6:W6) -> 0
A7: Ajonjoli blanco (kg) | M7: 25 | X7: =SUM(C7:W7) -> 25
X8: =SUM(C8:W8) -> 0
A9: Ajonjoli negro (kg) | K9: 100 | X9: =SUM(C9:W9) -> 100
X10: =SUM(C10:W10) -> 0
A11: Almidón | C11: 196 | D11: 126 | E11: 126 | F11: 84 | G11: 14 | X11: =SUM(C11:W11) -> 546
X12: =SUM(C12:W12) -> 0
A13: Anis (kg) | D13: 2.4 | E13: 3.6 | F13: 3 | G13: 3 | X13: =SUM(C13:W13) -> 12
X14: =SUM(C14:W14) -> 0
A15: Azucar (kg) | C15: 700 | D15: 530 | E15: 570 | F15: 400 | G15: 150 | H15: 60 | I15: 120 | J15: 15 | X15: =SUM(C15:W15) -> 2545
X16: =SUM(C16:W16) -> 0
A17: Benzoato | X17: =SUM(C17:W17) -> 0
H18: 0.42 | I18: 0.84 | X18: =SUM(C18:W18) -> 1.26
A19: Cacahuate (kg) | K19: 160 | M19: 30 | X19: =SUM(C19:W19) -> 190
X20: =SUM(C20:W20) -> 0
A21: Canela (kg) | D21: 1 | E21: 1.5 | F21: 1.25 | G21: 1.25 | X21: =SUM(C21:W21) -> 5
X22: =SUM(C22:W22) -> 0
A23: Caramelo (L) | D23: 8 | E23: 12 | F23: 10 | G23: 10 | X23: =SUM(C23:W23) -> 40
X24: =SUM(C24:W24) -> 0
A25: Cebolla molida | C25: 5.6 | D25: 3.6 | E25: 3.6 | F25: 2.4 | G25: 0.6 | X25: =SUM(C25:W25) -> 15.8
X26: =SUM(C26:W26) -> 0
A27: Chile ancho | X27: =SUM(C27:W27) -> 0
M28: 11 | X28: =SUM(C28:W28) -> 11
A29: Chile chipotle | H29: 45 | I29: 90 | X29: =SUM(C29:W29) -> 135
X30: =SUM(C30:W30) -> 0
A31: Chile guajillo | M31: 15 | X31: =SUM(C31:W31) -> 15
X32: =SUM(C32:W32) -> 0
A33: Chile pasilla molido (kg) | K33: 30 | X33: =SUM(C33:W33) -> 30
X34: =SUM(C34:W34) -> 0
A35: Chocolate (kg) | D35: 6 | E35: 9 | F35: 7.5 | G35: 7.5 | X35: =SUM(C35:W35) -> 30
X36: =SUM(C36:W36) -> 0
A37: Clavo (kg) | D37: 0.4 | E37: 0.6 | F37: 0.5 | G37: 0.5 | X37: =SUM(C37:W37) -> 2
X38: =SUM(C38:W38) -> 0
A39: Comino | X39: =SUM(C39:W39) -> 0
X40: =SUM(C40:W40) -> 0
...
